Workbook

Sheet Panduan
A1: APZACCT — PANDUAN SISTEM PERAKAUNAN (v1.3)
A3: Apa buku kerja ini
A4: Sistem perakaunan berganda (double-entry): setiap transaksi ada sekurang-kurangnya dua baris — Debit dan Kredit — dengan jumlah sama. Anda hanya merekod transaksi; Imbangan Duga, UR (Untung Rugi), KKK (Kunci Kira-Kira) dan AT (Aliran Tunai) dikira sendiri oleh formula. Jangan taip angka terus ke helaian penyata (Imbangan_Duga, UR, KKK, AT, APK, Cetak).
A6: Tiga cara merekod
A7: 1) Wizard web (menu APZacct > Buka APZacct) — untuk transaksi yang melibatkan wang masuk/keluar: Terimaan, Bayaran, dan Kontra (pindahan antara akaun wang sendiri).
A8: 2) Menu APZacct dalam Sheets — untuk kemasukan khas: Pos Baki Pembukaan (baki awal), Jurnal Laras (terakru / prabayar / pelarasan tanpa pergerakan wang), Pos Susut Nilai Aset, Pos Agihan APK.
A9: 3) Taip terus di Transaksi + Baris_Transaksi — hanya jika terpaksa. Satu transaksi = satu baris tajuk di Transaksi + sekurang-kurangnya dua baris di Baris_Transaksi dengan ID Transaksi yang sama; jumlah Debit mesti sama Kredit.
A11: Cara helaian berkait
A12: Akaun (senarai akaun: Kod, Jenis, Kumpulan Aliran Tunai) → Transaksi (tajuk: tarikh, perkara, rujukan) + Baris_Transaksi (baris Debit/Kredit = lejar sebenar) → Imbangan_Duga (jumlah setiap akaun) → UR, KKK, AT, APK → Cetak (versi cetak / PDF).
A13: Lajur G dan H di Baris_Transaksi ialah AUTO (Kumpulan Aliran Tunai dan Jenis akaun) — jangan taip.
A14: Tetapan = nama, kadar, tarikh kunci, URL web app. Baki_Pembukaan = baki awal (dipos melalui menu). Daftar_Aset_Tetap = aset dan susut nilai. Wang_Runcit = semakan kiraan tunai runcit. Log_Perubahan = rekod pindaan data yang sudah dipos (auto). Kamus_Istilah = maksud istilah.
A16: Kumpulan Aliran Tunai (auto) — apa maksudnya
... A44: Maksud istilah: Kamus_Istilah. Nama, kadar dan tarikh kunci: Tetapan (lajur C). Panduan penuh langkah demi langkah (Kontra, terakru/terdahulu, cara baca Imbangan Duga, Nota): fail APZacct_Panduan_Penggunaan.

Sheet Tetapan
A1: TETAPAN (SETTINGS)
A2: Lajur kuning (Nilai Digunakan) adalah SATU-SATUNYA lajur untuk diedit. Jangan sentuh helaian lain untuk tukar nilai ini.
A4: Tetapan | B4: Nilai Lalai (rujukan) | C4: Nilai Digunakan (edit di sini) | D4: Penerangan
A5: Nama Koperasi | B5: Koperasi Contoh Berhad | C5: [Isi nama koperasi sebenar di sini] | D5: Nama penuh untuk kepala setiap penyata rasmi
A6: No. Pendaftaran SKM | D6: Nombor pendaftaran rasmi dengan Suruhanjaya Koperasi Malaysia
A7: Bulan Mula Tahun Kewangan | B7: Januari | C7: Januari | D7: Bulan permulaan tahun kewangan koperasi (cth: Januari, April)
A8: Simbol Mata Wang | B8: RM | C8: RM | D8: Digunakan pada semua format nombor wang
A9: Bahasa Utama Aplikasi Web | B9: English | C9: English | D9: Bahasa lalai antara muka wizard; istilah perakaunan tetap ada tooltip BM (lihat Kamus_Istilah)
A10: Kod Akaun Seterusnya — Aset | B10: 1150 | C10: 1150 | D10: Kod kosong seterusnya dalam julat 1000-1999
A11: Kod Akaun Seterusnya — Liabiliti | B11: 2080 | C11: 2080 | D11: Kod kosong seterusnya dalam julat 2000-2999
A12: Kod Akaun Seterusnya — Ekuiti | B12: 3070 | C12: 3070 | D12: Kod kosong seterusnya dalam julat 3000-3999
A13: Kod Akaun Seterusnya — Hasil | B13: 4230 | C13: 4230 | D13: Kod kosong seterusnya dalam julat 4000-4999
A14: Kod Akaun Seterusnya — Perbelanjaan | B14: 5430 | C14: 5430 | D14: Kod kosong seterusnya dalam julat 5000-5999
A15: Kadar Rizab Statutori (%) | B15: 25 | C15: 25 | D15: s.57(1) Akta Koperasi 1993: 25% selagi Rizab < 50% Modal Syer+Yuran, jatuh ke 15% selepas itu - semak sendiri kedudukan semasa
A16: Kadar KWA Pendidikan Koperasi (%) | B16: 2 | C16: 2 | D16: Ikut arahan SKM semasa - sahkan kadar terkini
A17: Kadar KWA Pembangunan Koperasi (%) | B17: 1 | C17: 1 | D17: Ikut arahan SKM semasa - sahkan kadar terkini
A18: ID Transaksi Baki Pembukaan | D18: AT rujuk sel ini untuk kecualikan baki pembukaan daripada aliran tunai tempoh semasa. Skrip Tambah_Baki_Pembukaan.gs kemaskini ini automatik.
A19: Had Amaran Perbezaan Wang Runcit (RM) | B19: 10 | C19: 10
A20: URL Web App APZacct
A21: Tarikh Kunci Tempoh Kewangan | D21: Tarikh terakhir yang sudah dibentangkan kepada Lembaga - baris bertarikh pada atau sebelum ini akan ditanda amaran dalam Import Penyata Bank & Rekonsiliasi Bank. Kosongkan untuk nyahaktifkan amaran ini.
A22: Tahun Kewangan Susut Nilai Terakhir Dipos | D22: Diisi automatik oleh Pos Susut Nilai Aset selepas pos berjaya - jangan edit terus.
A23: Zon Masa (nama IANA, cth. Asia/Kuala_Lumpur) | B23: Asia/Kuala_Lumpur | C23: Asia/Kuala_Lumpur | D23: Menentukan "hari ini" bagi wizard dan skrip. UTC+8 = Asia/Kuala_Lumpur. Tukar jika perlu.

Sheet Kamus_Istilah
A1: KAMUS ISTILAH (BILINGUAL GLOSSARY)
A2: English = bahasa utama aplikasi web. Bahasa Malaysia = tooltip. Helaian ini boleh dibaca terus oleh wizard nanti.
A4: Istilah (English) | B4: Istilah (Bahasa Malaysia) | C4: Penerangan Ringkas
A5: Chart of Accounts | B5: Carta Akaun | C5: Senarai semua akaun yang koperasi guna, dengan jenis masing-masing
A6: Account | B6: Akaun | C6: Satu kategori tempat wang direkod, cth. Bank, Jualan, Perbelanjaan Pejabat
A7: Transaction | B7: Transaksi | C7: Satu peristiwa kewangan, cth. satu resit atau satu PV
A8: Debit | B8: Debit | C8: Sisi kiri catatan berganda; menambah Aset/Perbelanjaan, mengurang Liabiliti/Ekuiti/Hasil
A9: Credit | B9: Kredit | C9: Sisi kanan catatan berganda; menambah Liabiliti/Ekuiti/Hasil, mengurang Aset/Perbelanjaan
A10: Trial Balance | B10: Imbangan Duga | C10: Senarai semua baki akaun; jumlah Debit mesti sama dengan jumlah Kredit
A11: Balance Sheet | B11: Kunci Kira-Kira (KKK) | C11: Kedudukan Aset, Liabiliti dan Ekuiti pada satu tarikh
A12: Income Statement | B12: Akaun Untung Rugi (UR) | C12: Hasil tolak Perbelanjaan bagi satu tempoh
A13: Cash Flow Statement | B13: Penyata Aliran Tunai (AT) | C13: Pergerakan tunai masuk dan keluar bagi satu tempoh
A14: Opening Balance | B14: Baki Awal / Pembukaan | C14: Baki setiap akaun pada permulaan tahun kewangan baharu
A15: Member Equity | B15: Ekuiti Ahli | C15: Modal syer, rizab dan lebihan terkumpul kepunyaan ahli koperasi
... A64: Late (Backdated) Entry | B64: Entri Lewat | C64: Transaksi bertarikh dalam tempoh yang sudah dikunci (Tetapan!C21); perlu sebab dan ditanda "Entri Lewat".

Sheet Akaun
A1: CARTA AKAUN (CHART OF ACCOUNTS)
A2: Setiap baris ialah SATU akaun. Lajur I = Semasa/Bukan Semasa (Aset & Liabiliti sahaja, ikut format KKK rasmi).
A4: Kod Akaun | B4: Nama Akaun (EN) | C4: Nama Akaun (BM) | D4: Jenis | E4: Baki Normal | F4: Kumpulan Aliran Tunai | G4: Status | H4: Nota | I4: Semasa/Bukan Semasa
A5: 1010 | B5: Cash in hand | C5: Wang Di Tangan | D5: Aset | E5: =IF(OR(D5="Aset",D5="Perbelanjaan"),"Debit","Kredit") -> Debit | F5: Tidak Berkaitan | G5: Aktif | I5: Semasa
A6: 1020 | B6: Bank | C6: Bank | D6: Aset | E6: =IF(OR(D6="Aset",D6="Perbelanjaan"),"Debit","Kredit") -> Debit | F6: Tidak Berkaitan | G6: Aktif | I6: Semasa
A7: 1030 | B7: Fixed Deposit | C7: Deposit Tetap | D7: Aset | E7: =IF(OR(D7="Aset",D7="Perbelanjaan"),"Debit","Kredit") -> Debit | F7: Pelaburan | G7: Aktif | I7: Bukan Semasa
A8: 1040 | B8: Fixed Assets (general) | C8: Aset Tetap | D8: Aset | E8: =IF(OR(D8="Aset",D8="Perbelanjaan"),"Debit","Kredit") -> Debit | F8: Pelaburan | G8: Aktif | H8: Pecahkan Tanah/Bangunan/Kenderaan bila disahkan pemilikan sebenar | I8: Bukan Semasa
A9: 1050 | B9: Cooperative Deposit Account | C9: Akaun Deposit Koperasi | D9: Aset | E9: =IF(OR(D9="Aset",D9="Perbelanjaan"),"Debit","Kredit") -> Debit | F9: Pelaburan | G9: Aktif | H9: DIBETULKAN: Aset Bukan Semasa ikut format KKK rasmi (bukan Liabiliti seperti anggapan asal) | I9: Bukan Semasa
A10: 1060 | B10: Retail Inventory | C10: Inventori Runcit | D10: Aset | E10: =IF(OR(D10="Aset",D10="Perbelanjaan"),"Debit","Kredit") -> Debit | F10: Operasi | G10: Aktif | I10: Semasa
A11: 1070 | B11: Poultry & Slaughter Product Inventory | C11: Inventori Ayam & Produk Sembelihan | D11: Aset | E11: =IF(OR(D11="Aset",D11="Perbelanjaan"),"Debit","Kredit") -> Debit | F11: Operasi | G11: Aktif | I11: Semasa
A12: 2010 | B12: Various Creditors | C12: Pelbagai Pemiutang | D12: Liabiliti | E12: =IF(OR(D12="Aset",D12="Perbelanjaan"),"Debit","Kredit") -> Kredit | F12: Operasi | G12: Aktif | I12: Semasa
A13: 2020 | B13: Dividend Declared | C13: Dividen Diisytiharkan | D13: Liabiliti | E13: =IF(OR(D13="Aset",D13="Perbelanjaan"),"Debit","Kredit") -> Kredit | F13: Berkanun | G13: Aktif | I13: Semasa
A14: 3010 | B14: Member Share Capital | C14: Modal Syer Ahli | D14: Ekuiti | E14: =IF(OR(D14="Aset",D14="Perbelanjaan"),"Debit","Kredit") -> Kredit | F14: Pembiayaan | G14: Aktif
A15: 3020 | B15: Statutory Reserve | C15: Rizab Statutori | D15: Ekuiti | E15: =IF(OR(D15="Aset",D15="Perbelanjaan"),"Debit","Kredit") -> Kredit | F15: Tidak Berkaitan | G15: Aktif | H15: Wajib di bawah Akta Koperasi 1993
A16: 3030 | B16: Accumulated Surplus | C16: Lebihan Terkumpul | D16: Ekuiti | E16: =IF(OR(D16="Aset",D16="Perbelanjaan"),"Debit","Kredit") -> Kredit | F16: Tidak Berkaitan | G16: Aktif
A17: 4010 | B17: Entrance Fee | C17: Fi Masuk | D17: Hasil | E17: =IF(OR(D17="Aset",D17="Perbelanjaan"),"Debit","Kredit") -> Kredit | F17: Operasi | G17: Aktif
A18: 4020 | B18: Bank Interest (conventional) | C18: Faedah Bank | D18: Hasil | E18: =IF(OR(D18="Aset",D18="Perbelanjaan"),"Debit","Kredit") -> Kredit | F18: Operasi | G18: Aktif
A19: 4030 | B19: Bank Hibah (Islamic) | C19: Hibah Bank | D19: Hasil | E19: =IF(OR(D19="Aset",D19="Perbelanjaan"),"Debit","Kredit") -> Kredit | F19: Operasi | G19: Aktif
A20: 4040 | B20: Retail Sales | C20: Jualan Runcit | D20: Hasil | E20: =IF(OR(D20="Aset",D20="Perbelanjaan"),"Debit","Kredit") -> Kredit | F20: Operasi | G20: Aktif
A21: 4050 | B21: Service Income | C21: Pendapatan Perkhidmatan | D21: Hasil | E21: =IF(OR(D21="Aset",D21="Perbelanjaan"),"Debit","Kredit") -> Kredit | F21: Operasi | G21: Aktif
A22: 4060 | B22: Training & Course Income | C22: Pendapatan Latihan & Kursus | D22: Hasil | E22: =IF(OR(D22="Aset",D22="Perbelanjaan"),"Debit","Kredit") -> Kredit | F22: Operasi | G22: Aktif
A23: 4070 | B23: F&B Sales | C23: Jualan Makanan & Minuman | D23: Hasil | E23: =IF(OR(D23="Aset",D23="Perbelanjaan"),"Debit","Kredit") -> Kredit | F23: Operasi | G23: Aktif
A24: 4080 | B24: Halal Poultry & Slaughter Product Sales | C24: Jualan Ayam & Produk Sembelihan | D24: Hasil | E24: =IF(OR(D24="Aset",D24="Perbelanjaan"),"Debit","Kredit") -> Kredit | F24: Operasi | G24: Aktif
A25: 5010 | B25: Office Expenses | C25: Perbelanjaan Pejabat | D25: Perbelanjaan | E25: =IF(OR(D25="Aset",D25="Perbelanjaan"),"Debit","Kredit") -> Debit | F25: Operasi | G25: Aktif
A26: 5020 | B26: Board Expenses | C26: Perbelanjaan Lembaga | D26: Perbelanjaan | E26: =IF(OR(D26="Aset",D26="Perbelanjaan"),"Debit","Kredit") -> Debit | F26: Operasi | G26: Aktif
A27: 5030 | B27: Salaries and Allowances | C27: Gaji dan Elaun | D27: Perbelanjaan | E27: =IF(OR(D27="Aset",D27="Perbelanjaan"),"Debit","Kredit") -> Debit | F27: Operasi | G27: Aktif
... A33: 5090 | B33: AGM Expenses — Special/EGM | C33: Perbelanjaan Mesyuarat Agung Khas | D33: Perbelanjaan | E33: =IF(OR(D33="Aset",D33="Perbelanjaan"),"Debit","Kredit") -> Debit | F33: Operasi | G33: Aktif
A34: 5100 | B34: Board Honorarium | C34: Honorarium ALK | D34: Perbelanjaan | E34: =IF(OR(D34="Aset",D34="Perbelanjaan"),"Debit","Kredit") -> Debit | F34: Operasi | G34: Tidak Aktif | H34: DIPINDAH ke APK sebagai pembahagian keuntungan, bukan perbelanjaan operasi - lihat akaun liabiliti gantian
A35: 5110 | B35: Income Tax | C35: Cukai Pendapatan | D35: Perbelanjaan | E35: =IF(OR(D35="Aset",D35="Perbelanjaan"),"Debit","Kredit") -> Debit | F35: Operasi | G35: Tidak Aktif | H35: DIPINDAH ke APK sebagai pembahagian keuntungan, bukan perbelanjaan operasi - lihat akaun liabiliti gantian
A36: 5120 | B36: Zakat | C36: Zakat | D36: Perbelanjaan | E36: =IF(OR(D36="Aset",D36="Perbelanjaan"),"Debit","Kredit") -> Debit | F36: Operasi | G36: Tidak Aktif | H36: DIPINDAH ke APK sebagai pembahagian keuntungan, bukan perbelanjaan operasi - lihat akaun liabiliti gantian
A37: 5130 | B37: Cooperative Education Fund | C37: Bayaran KWA Pendidikan Koperasi | D37: Perbelanjaan | E37: =IF(OR(D37="Aset",D37="Perbelanjaan"),"Debit","Kredit") -> Debit | F37: Operasi | G37: Tidak Aktif | H37: DIPINDAH ke APK sebagai pembahagian keuntungan, bukan perbelanjaan operasi - lihat akaun liabiliti gantian
A38: 5140 | B38: Cooperative Development Fund | C38: Bayaran KWA Pembangunan Koperasi | D38: Perbelanjaan | E38: =IF(OR(D38="Aset",D38="Perbelanjaan"),"Debit","Kredit") -> Debit | F38: Operasi | G38: Tidak Aktif | H38: DIPINDAH ke APK sebagai pembahagian keuntungan, bukan perbelanjaan operasi - lihat akaun liabiliti gantian
A39: 5150 | B39: Internet and Telephone | C39: Internet dan Telefon | D39: Perbelanjaan | E39: =IF(OR(D39="Aset",D39="Perbelanjaan"),"Debit","Kredit") -> Debit | F39: Operasi | G39: Aktif
A40: 5160 | B40: Depreciation | C40: Susut Nilai Aset | D40: Perbelanjaan | E40: =IF(OR(D40="Aset",D40="Perbelanjaan"),"Debit","Kredit") -> Debit | F40: Operasi | G40: Aktif
A41: 5170 | B41: Miscellaneous Expenses | C41: Pelbagai Perbelanjaan | D41: Perbelanjaan | E41: =IF(OR(D41="Aset",D41="Perbelanjaan"),"Debit","Kredit") -> Debit | F41: Operasi | G41: Aktif | H41: Tangkapan am
A42: 5180 | B42: Retail Purchases (COGS) | C42: Belian Runcit | D42: Perbelanjaan | E42: =IF(OR(D42="Aset",D42="Perbelanjaan"),"Debit","Kredit") -> Debit | F42: Operasi | G42: Aktif
A43: 5190 | B43: Training & Course Costs | C43: Kos Latihan & Kursus | D43: Perbelanjaan | E43: =IF(OR(D43="Aset",D43="Perbelanjaan"),"Debit","Kredit") -> Debit | F43: Operasi | G43: Aktif
A44: 5200 | B44: F&B Raw Material Cost | C44: Kos Bahan Mentah F&B | D44: Perbelanjaan | E44: =IF(OR(D44="Aset",D44="Perbelanjaan"),"Debit","Kredit") -> Debit | F44: Operasi | G44: Aktif
A45: 5210 | B45: Live Chicken Purchases | C45: Belian Ayam Hidup | D45: Perbelanjaan | E45: =IF(OR(D45="Aset",D45="Perbelanjaan"),"Debit","Kredit") -> Debit | F45: Operasi | G45: Aktif
A46: 5220 | B46: Slaughtering & Processing Cost | C46: Kos Sembelihan & Pemprosesan | D46: Perbelanjaan | E46: =IF(OR(D46="Aset",D46="Perbelanjaan"),"Debit","Kredit") -> Debit | F46: Operasi | G46: Aktif
...

Sheet Baki_Pembukaan
A1: BAKI PEMBUKAAN (OPENING BALANCES)
A2: Guna angka daripada penyata kewangan TERAUDIT tahun lepas SAHAJA. Hanya untuk akaun Aset/Liabiliti/Ekuiti - Hasil dan Perbelanjaan tidak patut ada baki pembukaan (ia bermula sifar setiap tahun kewangan baharu). Isi Kod Akaun dan SATU sahaja daripada Debit/Kredit setiap baris ikut baki normal akaun itu, kemudian jalankan menu APZacct > Pos Baki Pembukaan.
A4: Kod Akaun | B4: Nama Akaun (auto) | C4: Jenis (auto) | D4: Debit | E4: Kredit | F4: Status
B5: {=IFERROR(INDEX(Akaun!$C$5:$C$150,MATCH(A5,Akaun!$A$5:$A$150,0)),"")} | C5: {=IFERROR(INDEX(Akaun!$D$5:$D$150,MATCH(A5,Akaun!$A$5:$A$150,0)),"")}
B6: {=IFERROR(INDEX(Akaun!$C$5:$C$150,MATCH(A6,Akaun!$A$5:$A$150,0)),"")} | C6: {=IFERROR(INDEX(Akaun!$D$5:$D$150,MATCH(A6,Akaun!$A$5:$A$150,0)),"")}
B7: {=IFERROR(INDEX(Akaun!$C$5:$C$150,MATCH(A7,Akaun!$A$5:$A$150,0)),"")} | C7: {=IFERROR(INDEX(Akaun!$D$5:$D$150,MATCH(A7,Akaun!$A$5:$A$150,0)),"")}
B8: {=IFERROR(INDEX(Akaun!$C$5:$C$150,MATCH(A8,Akaun!$A$5:$A$150,0)),"")} | C8: {=IFERROR(INDEX(Akaun!$D$5:$D$150,MATCH(A8,Akaun!$A$5:$A$150,0)),"")}
B9: {=IFERROR(INDEX(Akaun!$C$5:$C$150,MATCH(A9,Akaun!$A$5:$A$150,0)),"")} | C9: {=IFERROR(INDEX(Akaun!$D$5:$D$150,MATCH(A9,Akaun!$A$5:$A$150,0)),"")}
B10: {=IFERROR(INDEX(Akaun!$C$5:$C$150,MATCH(A10,Akaun!$A$5:$A$150,0)),"")} | C10: {=IFERROR(INDEX(Akaun!$D$5:$D$150,MATCH(A10,Akaun!$A$5:$A$150,0)),"")}
B11: {=IFERROR(INDEX(Akaun!$C$5:$C$150,MATCH(A11,Akaun!$A$5:$A$150,0)),"")} | C11: {=IFERROR(INDEX(Akaun!$D$5:$D$150,MATCH(A11,Akaun!$A$5:$A$150,0)),"")}
B12: {=IFERROR(INDEX(Akaun!$C$5:$C$150,MATCH(A12,Akaun!$A$5:$A$150,0)),"")} | C12: {=IFERROR(INDEX(Akaun!$D$5:$D$150,MATCH(A12,Akaun!$A$5:$A$150,0)),"")}
B13: {=IFERROR(INDEX(Akaun!$C$5:$C$150,MATCH(A13,Akaun!$A$5:$A$150,0)),"")} | C13: {=IFERROR(INDEX(Akaun!$D$5:$D$150,MATCH(A13,Akaun!$A$5:$A$150,0)),"")}
B14: {=IFERROR(INDEX(Akaun!$C$5:$C$150,MATCH(A14,Akaun!$A$5:$A$150,0)),"")} | C14: {=IFERROR(INDEX(Akaun!$D$5:$D$150,MATCH(A14,Akaun!$A$5:$A$150,0)),"")}
B15: {=IFERROR(INDEX(Akaun!$C$5:$C$150,MATCH(A15,Akaun!$A$5:$A$150,0)),"")} | C15: {=IFERROR(INDEX(Akaun!$D$5:$D$150,MATCH(A15,Akaun!$A$5:$A$150,0)),"")}
B16: {=IFERROR(INDEX(Akaun!$C$5:$C$150,MATCH(A16,Akaun!$A$5:$A$150,0)),"")} | C16: {=IFERROR(INDEX(Akaun!$D$5:$D$150,MATCH(A16,Akaun!$A$5:$A$150,0)),"")}
... B54: {=IFERROR(INDEX(Akaun!$C$5:$C$150,MATCH(A54,Akaun!$A$5:$A$150,0)),"")} | C54: {=IFERROR(INDEX(Akaun!$D$5:$D$150,MATCH(A54,Akaun!$A$5:$A$150,0)),"")}
A57: Jumlah | D57: =SUM(D5:D54) -> 0 | E57: =SUM(E5:E54) -> 0
A58: Semakan (mesti sepadan sebelum pos) | B58: =IF(ROUND(D57-E57,2)=0,"SEIMBANG - sedia untuk pos","TIDAK SEIMBANG - beza RM"&TEXT(D57-E57,"#,##0.00")) -> SEIMBANG - sedia untuk pos

Sheet Daftar_Aset_Tetap
A1: DAFTAR ASET TETAP (FIXED ASSET REGISTER)
A2: Sub-lejar terperinci di sebalik akaun kawalan "Aset Tetap" (1040) dalam Akaun. Jumlah Nilai Buku Bersih di sini SEPATUTNYA sepadan dengan baki 1040 tolak 1045 di Imbangan_Duga - jika tidak, ada aset didaftar di sini tanpa dipos ke lejar, atau sebaliknya.
A4: Nama Aset | B4: Kategori | C4: Tarikh Perolehan | D4: Kos Asal (RM) | E4: Nilai Baki (RM) | F4: Jangka Hayat (tahun) | G4: Kaedah | H4: Kadar Baki Berkurangan (%) | I4: Susut Nilai Terkumpul (RM) | J4: Nilai Buku Bersih (RM) | K4: Susut Nilai Tahun Ini (RM)
I5: =IF(OR(D5="",F5=""),"",IF(G5="Baki Berkurangan",MIN(D5*(1-(1-H5/100)^MAX(0,MIN(YEARFRAC(C5,TODAY(),1),F5))),D5-E5),MIN(((D5-E5)/F5)*MAX(0,MIN(YEARFRAC(C5,TODAY(),1),F5)),D5-E5))) | J5: =IF(D5="","",D5-I5) | K5: =IF(D5="","",I5-(IF(G5="Baki Berkurangan",MIN(D5*(1-(1-H5/100)^MAX(0,MIN(YEARFRAC(C5,TODAY(),1)-1,F5))),D5-E5),MIN(((D5-E5)/F5)*MAX(0,MIN(YEARFRAC(C5,TODAY(),1)-1,F5)),D5-E5))))
I6: =IF(OR(D6="",F6=""),"",IF(G6="Baki Berkurangan",MIN(D6*(1-(1-H6/100)^MAX(0,MIN(YEARFRAC(C6,TODAY(),1),F6))),D6-E6),MIN(((D6-E6)/F6)*MAX(0,MIN(YEARFRAC(C6,TODAY(),1),F6)),D6-E6))) | J6: =IF(D6="","",D6-I6) | K6: =IF(D6="","",I6-(IF(G6="Baki Berkurangan",MIN(D6*(1-(1-H6/100)^MAX(0,MIN(YEARFRAC(C6,TODAY(),1)-1,F6))),D6-E6),MIN(((D6-E6)/F6)*MAX(0,MIN(YEARFRAC(C6,TODAY(),1)-1,F6)),D6-E6))))
I7: =IF(OR(D7="",F7=""),"",IF(G7="Baki Berkurangan",MIN(D7*(1-(1-H7/100)^MAX(0,MIN(YEARFRAC(C7,TODAY()),F7))),D7-E7),MIN(((D7-E7)/F7)*MAX(0,MIN(YEARFRAC(C7,TODAY()),F7)),D7-E7))) | J7: =IF(D7="","",D7-I7) | K7: =IF(D7="","",I7-(IF(G7="Baki Berkurangan",MIN(D7*(1-(1-H7/100)^MAX(0,MIN(YEARFRAC(C7,TODAY())-1,F7))),D7-E7),MIN(((D7-E7)/F7)*MAX(0,MIN(YEARFRAC(C7,TODAY())-1,F7)),D7-E7))))
I8: =IF(OR(D8="",F8=""),"",IF(G8="Baki Berkurangan",MIN(D8*(1-(1-H8/100)^MAX(0,MIN(YEARFRAC(C8,TODAY()),F8))),D8-E8),MIN(((D8-E8)/F8)*MAX(0,MIN(YEARFRAC(C8,TODAY()),F8)),D8-E8))) | J8: =IF(D8="","",D8-I8) | K8: =IF(D8="","",I8-(IF(G8="Baki Berkurangan",MIN(D8*(1-(1-H8/100)^MAX(0,MIN(YEARFRAC(C8,TODAY())-1,F8))),D8-E8),MIN(((D8-E8)/F8)*MAX(0,MIN(YEARFRAC(C8,TODAY())-1,F8)),D8-E8))))
I9: =IF(OR(D9="",F9=""),"",IF(G9="Baki Berkurangan",MIN(D9*(1-(1-H9/100)^MAX(0,MIN(YEARFRAC(C9,TODAY()),F9))),D9-E9),MIN(((D9-E9)/F9)*MAX(0,MIN(YEARFRAC(C9,TODAY()),F9)),D9-E9))) | J9: =IF(D9="","",D9-I9) | K9: =IF(D9="","",I9-(IF(G9="Baki Berkurangan",MIN(D9*(1-(1-H9/100)^MAX(0,MIN(YEARFRAC(C9,TODAY())-1,F9))),D9-E9),MIN(((D9-E9)/F9)*MAX(0,MIN(YEARFRAC(C9,TODAY())-1,F9)),D9-E9))))
I10: =IF(OR(D10="",F10=""),"",IF(G10="Baki Berkurangan",MIN(D10*(1-(1-H10/100)^MAX(0,MIN(YEARFRAC(C10,TODAY()),F10))),D10-E10),MIN(((D10-E10)/F10)*MAX(0,MIN(YEARFRAC(C10,TODAY()),F10)),D10-E10))) | J10: =IF(D10="","",D10-I10) | K10: =IF(D10="","",I10-(IF(G10="Baki Berkurangan",MIN(D10*(1-(1-H10/100)^MAX(0,MIN(YEARFRAC(C10,TODAY())-1,F10))),D10-E10),MIN(((D10-E10)/F10)*MAX(0,MIN(YEARFRAC(C10,TODAY())-1,F10)),D10-E10))))
I11: =IF(OR(D11="",F11=""),"",IF(G11="Baki Berkurangan",MIN(D11*(1-(1-H11/100)^MAX(0,MIN(YEARFRAC(C11,TODAY()),F11))),D11-E11),MIN(((D11-E11)/F11)*MAX(0,MIN(YEARFRAC(C11,TODAY()),F11)),D11-E11))) | J11: =IF(D11="","",D11-I11) | K11: =IF(D11="","",I11-(IF(G11="Baki Berkurangan",MIN(D11*(1-(1-H11/100)^MAX(0,MIN(YEARFRAC(C11,TODAY())-1,F11))),D11-E11),MIN(((D11-E11)/F11)*MAX(0,MIN(YEARFRAC(C11,TODAY())-1,F11)),D11-E11))))
I12: =IF(OR(D12="",F12=""),"",IF(G12="Baki Berkurangan",MIN(D12*(1-(1-H12/100)^MAX(0,MIN(YEARFRAC(C12,TODAY()),F12))),D12-E12),MIN(((D12-E12)/F12)*MAX(0,MIN(YEARFRAC(C12,TODAY()),F12)),D12-E12))) | J12: =IF(D12="","",D12-I12) | K12: =IF(D12="","",I12-(IF(G12="Baki Berkurangan",MIN(D12*(1-(1-H12/100)^MAX(0,MIN(YEARFRAC(C12,TODAY())-1,F12))),D12-E12),MIN(((D12-E12)/F12)*MAX(0,MIN(YEARFRAC(C12,TODAY())-1,F12)),D12-E12))))
I13: =IF(OR(D13="",F13=""),"",IF(G13="Baki Berkurangan",MIN(D13*(1-(1-H13/100)^MAX(0,MIN(YEARFRAC(C13,TODAY()),F13))),D13-E13),MIN(((D13-E13)/F13)*MAX(0,MIN(YEARFRAC(C13,TODAY()),F13)),D13-E13))) | J13: =IF(D13="","",D13-I13) | K13: =IF(D13="","",I13-(IF(G13="Baki Berkurangan",MIN(D13*(1-(1-H13/100)^MAX(0,MIN(YEARFRAC(C13,TODAY())-1,F13))),D13-E13),MIN(((D13-E13)/F13)*MAX(0,MIN(YEARFRAC(C13,TODAY())-1,F13)),D13-E13))))
I14: =IF(OR(D14="",F14=""),"",IF(G14="Baki Berkurangan",MIN(D14*(1-(1-H14/100)^MAX(0,MIN(YEARFRAC(C14,TODAY()),F14))),D14-E14),MIN(((D14-E14)/F14)*MAX(0,MIN(YEARFRAC(C14,TODAY()),F14)),D14-E14))) | J14: =IF(D14="","",D14-I14) | K14: =IF(D14="","",I14-(IF(G14="Baki Berkurangan",MIN(D14*(1-(1-H14/100)^MAX(0,MIN(YEARFRAC(C14,TODAY())-1,F14))),D14-E14),MIN(((D14-E14)/F14)*MAX(0,MIN(YEARFRAC(C14,TODAY())-1,F14)),D14-E14))))
I15: =IF(OR(D15="",F15=""),"",IF(G15="Baki Berkurangan",MIN(D15*(1-(1-H15/100)^MAX(0,MIN(YEARFRAC(C15,TODAY()),F15))),D15-E15),MIN(((D15-E15)/F15)*MAX(0,MIN(YEARFRAC(C15,TODAY()),F15)),D15-E15))) | J15: =IF(D15="","",D15-I15) | K15: =IF(D15="","",I15-(IF(G15="Baki Berkurangan",MIN(D15*(1-(1-H15/100)^MAX(0,MIN(YEARFRAC(C15,TODAY())-1,F15))),D15-E15),MIN(((D15-E15)/F15)*MAX(0,MIN(YEARFRAC(C15,TODAY())-1,F15)),D15-E15))))
I16: =IF(OR(D16="",F16=""),"",IF(G16="Baki Berkurangan",MIN(D16*(1-(1-H16/100)^MAX(0,MIN(YEARFRAC(C16,TODAY()),F16))),D16-E16),MIN(((D16-E16)/F16)*MAX(0,MIN(YEARFRAC(C16,TODAY()),F16)),D16-E16))) | J16: =IF(D16="","",D16-I16) | K16: =IF(D16="","",I16-(IF(G16="Baki Berkurangan",MIN(D16*(1-(1-H16/100)^MAX(0,MIN(YEARFRAC(C16,TODAY())-1,F16))),D16-E16),MIN(((D16-E16)/F16)*MAX(0,MIN(YEARFRAC(C16,TODAY())-1,F16)),D16-E16))))
I17: =IF(OR(D17="",F17=""),"",IF(G17="Baki Berkurangan",MIN(D17*(1-(1-H17/100)^MAX(0,MIN(YEARFRAC(C17,TODAY()),F17))),D17-E17),MIN(((D17-E17)/F17)*MAX(0,MIN(YEARFRAC(C17,TODAY()),F17)),D17-E17))) | J17: =IF(D17="","",D17-I17) | K17: =IF(D17="","",I17-(IF(G17="Baki Berkurangan",MIN(D17*(1-(1-H17/100)^MAX(0,MIN(YEARFRAC(C17,TODAY())-1,F17))),D17-E17),MIN(((D17-E17)/F17)*MAX(0,MIN(YEARFRAC(C17,TODAY())-1,F17)),D17-E17))))
I18: =IF(OR(D18="",F18=""),"",IF(G18="Baki Berkurangan",MIN(D18*(1-(1-H18/100)^MAX(0,MIN(YEARFRAC(C18,TODAY()),F18))),D18-E18),MIN(((D18-E18)/F18)*MAX(0,MIN(YEARFRAC(C18,TODAY()),F18)),D18-E18))) | J18: =IF(D18="","",D18-I18) | K18: =IF(D18="","",I18-(IF(G18="Baki Berkurangan",MIN(D18*(1-(1-H18/100)^MAX(0,MIN(YEARFRAC(C18,TODAY())-1,F18))),D18-E18),MIN(((D18-E18)/F18)*MAX(0,MIN(YEARFRAC(C18,TODAY())-1,F18)),D18-E18))))
... I54: =IF(OR(D54="",F54=""),"",IF(G54="Baki Berkurangan",MIN(D54*(1-(1-H54/100)^MAX(0,MIN(YEARFRAC(C54,TODAY()),F54))),D54-E54),MIN(((D54-E54)/F54)*MAX(0,MIN(YEARFRAC(C54,TODAY()),F54)),D54-E54))) | J54: =IF(D54="","",D54-I54) | K54: =IF(D54="","",I54-(IF(G54="Baki Berkurangan",MIN(D54*(1-(1-H54/100)^MAX(0,MIN(YEARFRAC(C54,TODAY())-1,F54))),D54-E54),MIN(((D54-E54)/F54)*MAX(0,MIN(YEARFRAC(C54,TODAY())-1,F54)),D54-E54))))
A55: JUMLAH | D55: =SUM(D5:D54) -> 0 | I55: =SUM(I5:I54) -> 0 | J55: =SUM(J5:J54) -> 0 | K55: =SUM(K5:K54) -> 0
A57: Semakan lawan Akaun (1040 - 1045):
A58: Nilai Buku Bersih ikut Daftar (di atas) | B58: =J55 -> 0
A59: Nilai Buku Bersih ikut Lejar (Akaun 1040 - 1045) | B59: =SUMIF(Imbangan_Duga!$A$5:$A$150,1040,Imbangan_Duga!$H$5:$H$150)+SUMIF(Imbangan_Duga!$A$5:$A$150,1045,Imbangan_Duga!$H$5:$H$150) -> 0
A60: Semakan: | B60: =IF(ROUND(B58-B59,2)=0,"SEPADAN","TIDAK SEPADAN - beza RM"&TEXT(B58-B59,"#,##0.00")&" - ada aset didaftar tanpa dipos, atau sebaliknya") -> SEPADAN
A62: Nota ketepatan: "Susut Nilai Tahun Ini" (lajur K) disahkan tepat kepada sen untuk kedua-dua kaedah. "Susut Nilai Terkumpul" (lajur I, angka kumulatif sejak tarikh perolehan) mungkin berbeza beberapa ringgit sahaja daripada pengiraan manual disebabkan cara YEARFRAC kira bilangan hari - bukan ralat logik, hanya ketidaktepatan kecil pada angka kumulatif jangka panjang. Angka yang benar-benar dipos setiap tahun (lajur K) tidak terjejas.

Sheet Transaksi
A1: TRANSAKSI (TRANSACTION HEADERS)
A2: Satu baris = satu transaksi/resit/PV. Helaian ini kosong - transaksi masuk melalui wizard web APZacct atau menu APZacct.
A4: ID Transaksi | B4: Tarikh | C4: Perkara | D4: No. PV / Rujukan | E4: Kaedah | F4: Status | G4: URL Resit / Baucar

Sheet Baris_Transaksi
A1: BARIS TRANSAKSI (LEDGER LINES)
A2: Setiap transaksi ada 2+ baris. Jumlah Debit mesti sama dengan Jumlah Kredit bagi SETIAP ID Transaksi.
A4: ID Baris | B4: ID Transaksi | C4: Kod Akaun | D4: Debit | E4: Kredit | F4: Memo | G4: Kumpulan Aliran Tunai (auto) | H4: Jenis Akaun (auto)
G5: {=IF(C5="","",INDEX(Akaun!$F$5:$F$150,MATCH(C5,Akaun!$A$5:$A$150,0)))} | H5: =IF(C5="","",INDEX(Akaun!$D$5:$D$150,MATCH(C5,Akaun!$A$5:$A$150,0)))
G6: {=IF(C6="","",INDEX(Akaun!$F$5:$F$150,MATCH(C6,Akaun!$A$5:$A$150,0)))} | H6: =IF(C6="","",INDEX(Akaun!$D$5:$D$150,MATCH(C6,Akaun!$A$5:$A$150,0)))
G7: {=IF(C7="","",INDEX(Akaun!$F$5:$F$150,MATCH(C7,Akaun!$A$5:$A$150,0)))} | H7: =IF(C7="","",INDEX(Akaun!$D$5:$D$150,MATCH(C7,Akaun!$A$5:$A$150,0)))
G8: {=IF(C8="","",INDEX(Akaun!$F$5:$F$150,MATCH(C8,Akaun!$A$5:$A$150,0)))} | H8: =IF(C8="","",INDEX(Akaun!$D$5:$D$150,MATCH(C8,Akaun!$A$5:$A$150,0)))
G9: {=IF(C9="","",INDEX(Akaun!$F$5:$F$150,MATCH(C9,Akaun!$A$5:$A$150,0)))} | H9: =IF(C9="","",INDEX(Akaun!$D$5:$D$150,MATCH(C9,Akaun!$A$5:$A$150,0)))
G10: {=IF(C10="","",INDEX(Akaun!$F$5:$F$150,MATCH(C10,Akaun!$A$5:$A$150,0)))} | H10: =IF(C10="","",INDEX(Akaun!$D$5:$D$150,MATCH(C10,Akaun!$A$5:$A$150,0)))
G11: {=IF(C11="","",INDEX(Akaun!$F$5:$F$150,MATCH(C11,Akaun!$A$5:$A$150,0)))} | H11: =IF(C11="","",INDEX(Akaun!$D$5:$D$150,MATCH(C11,Akaun!$A$5:$A$150,0)))
G12: {=IF(C12="","",INDEX(Akaun!$F$5:$F$150,MATCH(C12,Akaun!$A$5:$A$150,0)))} | H12: =IF(C12="","",INDEX(Akaun!$D$5:$D$150,MATCH(C12,Akaun!$A$5:$A$150,0)))
G13: {=IF(C13="","",INDEX(Akaun!$F$5:$F$150,MATCH(C13,Akaun!$A$5:$A$150,0)))} | H13: =IF(C13="","",INDEX(Akaun!$D$5:$D$150,MATCH(C13,Akaun!$A$5:$A$150,0)))
G14: {=IF(C14="","",INDEX(Akaun!$F$5:$F$150,MATCH(C14,Akaun!$A$5:$A$150,0)))} | H14: =IF(C14="","",INDEX(Akaun!$D$5:$D$150,MATCH(C14,Akaun!$A$5:$A$150,0)))
G15: {=IF(C15="","",INDEX(Akaun!$F$5:$F$150,MATCH(C15,Akaun!$A$5:$A$150,0)))} | H15: =IF(C15="","",INDEX(Akaun!$D$5:$D$150,MATCH(C15,Akaun!$A$5:$A$150,0)))
G16: {=IF(C16="","",INDEX(Akaun!$F$5:$F$150,MATCH(C16,Akaun!$A$5:$A$150,0)))} | H16: =IF(C16="","",INDEX(Akaun!$D$5:$D$150,MATCH(C16,Akaun!$A$5:$A$150,0)))
... G500: {=IF(C500="","",INDEX(Akaun!$F$5:$F$150,MATCH(C500,Akaun!$A$5:$A$150,0)))} | H500: =IF(C500="","",INDEX(Akaun!$D$5:$D$150,MATCH(C500,Akaun!$A$5:$A$150,0)))
G501: =IF(C501="","",INDEX(Akaun!$F$5:$F$150,MATCH(C501,Akaun!$A$5:$A$150,0))) | H501: =IF(C501="","",INDEX(Akaun!$D$5:$D$150,MATCH(C501,Akaun!$A$5:$A$150,0)))
G502: =IF(C502="","",INDEX(Akaun!$F$5:$F$150,MATCH(C502,Akaun!$A$5:$A$150,0))) | H502: =IF(C502="","",INDEX(Akaun!$D$5:$D$150,MATCH(C502,Akaun!$A$5:$A$150,0)))
G503: =IF(C503="","",INDEX(Akaun!$F$5:$F$150,MATCH(C503,Akaun!$A$5:$A$150,0))) | H503: =IF(C503="","",INDEX(Akaun!$D$5:$D$150,MATCH(C503,Akaun!$A$5:$A$150,0)))
G504: =IF(C504="","",INDEX(Akaun!$F$5:$F$150,MATCH(C504,Akaun!$A$5:$A$150,0))) | H504: =IF(C504="","",INDEX(Akaun!$D$5:$D$150,MATCH(C504,Akaun!$A$5:$A$150,0)))
G505: =IF(C505="","",INDEX(Akaun!$F$5:$F$150,MATCH(C505,Akaun!$A$5:$A$150,0))) | H505: =IF(C505="","",INDEX(Akaun!$D$5:$D$150,MATCH(C505,Akaun!$A$5:$A$150,0)))
G506: =IF(C506="","",INDEX(Akaun!$F$5:$F$150,MATCH(C506,Akaun!$A$5:$A$150,0))) | H506: =IF(C506="","",INDEX(Akaun!$D$5:$D$150,MATCH(C506,Akaun!$A$5:$A$150,0)))
G507: =IF(C507="","",INDEX(Akaun!$F$5:$F$150,MATCH(C507,Akaun!$A$5:$A$150,0))) | H507: =IF(C507="","",INDEX(Akaun!$D$5:$D$150,MATCH(C507,Akaun!$A$5:$A$150,0)))
G508: =IF(C508="","",INDEX(Akaun!$F$5:$F$150,MATCH(C508,Akaun!$A$5:$A$150,0))) | H508: =IF(C508="","",INDEX(Akaun!$D$5:$D$150,MATCH(C508,Akaun!$A$5:$A$150,0)))
G509: =IF(C509="","",INDEX(Akaun!$F$5:$F$150,MATCH(C509,Akaun!$A$5:$A$150,0))) | H509: =IF(C509="","",INDEX(Akaun!$D$5:$D$150,MATCH(C509,Akaun!$A$5:$A$150,0)))
G510: =IF(C510="","",INDEX(Akaun!$F$5:$F$150,MATCH(C510,Akaun!$A$5:$A$150,0))) | H510: =IF(C510="","",INDEX(Akaun!$D$5:$D$150,MATCH(C510,Akaun!$A$5:$A$150,0)))
G511: =IF(C511="","",INDEX(Akaun!$F$5:$F$150,MATCH(C511,Akaun!$A$5:$A$150,0))) | H511: =IF(C511="","",INDEX(Akaun!$D$5:$D$150,MATCH(C511,Akaun!$A$5:$A$150,0)))
G512: =IF(C512="","",INDEX(Akaun!$F$5:$F$150,MATCH(C512,Akaun!$A$5:$A$150,0))) | H512: =IF(C512="","",INDEX(Akaun!$D$5:$D$150,MATCH(C512,Akaun!$A$5:$A$150,0)))
... G5000: =IF(C5000="","",INDEX(Akaun!$F$5:$F$150,MATCH(C5000,Akaun!$A$5:$A$150,0))) | H5000: =IF(C5000="","",INDEX(Akaun!$D$5:$D$150,MATCH(C5000,Akaun!$A$5:$A$150,0)))

Sheet Log_Perubahan
A1: Tarikh & Masa | B1: Pengguna | C1: Helaian | D1: Sel | E1: Nilai Lama | F1: Nilai Baharu | G1: Sebab

Sheet Imbangan_Duga
A1: IMBANGAN DUGA (TRIAL BALANCE)
A2: Formula pra-isi sampai baris 150 supaya akaun baharu (Tambah Akaun) automatik terpakai tanpa ubah julat.
A4: Kod Akaun | B4: Nama Akaun | C4: Jenis | D4: Jumlah Debit | E4: Jumlah Kredit | F4: Baki Debit | G4: Baki Kredit | H4: Baki Bersih (bertanda)
A5: =Akaun!A5 -> 1010 | B5: =Akaun!C5 -> Wang Di Tangan | C5: =Akaun!D5 -> Aset | D5: =SUMIF(Baris_Transaksi!$C$5:$C$5000,A5,Baris_Transaksi!$D$5:$D$5000) -> 0 | E5: =SUMIF(Baris_Transaksi!$C$5:$C$5000,A5,Baris_Transaksi!$E$5:$E$5000) -> 0 | F5: =IF(D5-E5>0,D5-E5,0) -> 0 | G5: =IF(E5-D5>0,E5-D5,0) -> 0 | H5: =IF(OR(C5="Aset",C5="Perbelanjaan"),D5-E5,E5-D5) -> 0
A6: =Akaun!A6 -> 1020 | B6: =Akaun!C6 -> Bank | C6: =Akaun!D6 -> Aset | D6: =SUMIF(Baris_Transaksi!$C$5:$C$5000,A6,Baris_Transaksi!$D$5:$D$5000) -> 0 | E6: =SUMIF(Baris_Transaksi!$C$5:$C$5000,A6,Baris_Transaksi!$E$5:$E$5000) -> 0 | F6: =IF(D6-E6>0,D6-E6,0) -> 0 | G6: =IF(E6-D6>0,E6-D6,0) -> 0 | H6: =IF(OR(C6="Aset",C6="Perbelanjaan"),D6-E6,E6-D6) -> 0
A7: =Akaun!A7 -> 1030 | B7: =Akaun!C7 -> Deposit Tetap | C7: =Akaun!D7 -> Aset | D7: =SUMIF(Baris_Transaksi!$C$5:$C$5000,A7,Baris_Transaksi!$D$5:$D$5000) -> 0 | E7: =SUMIF(Baris_Transaksi!$C$5:$C$5000,A7,Baris_Transaksi!$E$5:$E$5000) -> 0 | F7: =IF(D7-E7>0,D7-E7,0) -> 0 | G7: =IF(E7-D7>0,E7-D7,0) -> 0 | H7: =IF(OR(C7="Aset",C7="Perbelanjaan"),D7-E7,E7-D7) -> 0
A8: =Akaun!A8 -> 1040 | B8: =Akaun!C8 -> Aset Tetap | C8: =Akaun!D8 -> Aset | D8: =SUMIF(Baris_Transaksi!$C$5:$C$5000,A8,Baris_Transaksi!$D$5:$D$5000) -> 0 | E8: =SUMIF(Baris_Transaksi!$C$5:$C$5000,A8,Baris_Transaksi!$E$5:$E$5000) -> 0 | F8: =IF(D8-E8>0,D8-E8,0) -> 0 | G8: =IF(E8-D8>0,E8-D8,0) -> 0 | H8: =IF(OR(C8="Aset",C8="Perbelanjaan"),D8-E8,E8-D8) -> 0
A9: =Akaun!A9 -> 1050 | B9: =Akaun!C9 -> Akaun Deposit Koperasi | C9: =Akaun!D9 -> Aset | D9: =SUMIF(Baris_Transaksi!$C$5:$C$5000,A9,Baris_Transaksi!$D$5:$D$5000) -> 0 | E9: =SUMIF(Baris_Transaksi!$C$5:$C$5000,A9,Baris_Transaksi!$E$5:$E$5000) -> 0 | F9: =IF(D9-E9>0,D9-E9,0) -> 0 | G9: =IF(E9-D9>0,E9-D9,0) -> 0 | H9: =IF(OR(C9="Aset",C9="Perbelanjaan"),D9-E9,E9-D9) -> 0
A10: =Akaun!A10 -> 1060 | B10: =Akaun!C10 -> Inventori Runcit | C10: =Akaun!D10 -> Aset | D10: =SUMIF(Baris_Transaksi!$C$5:$C$5000,A10,Baris_Transaksi!$D$5:$D$5000) -> 0 | E10: =SUMIF(Baris_Transaksi!$C$5:$C$5000,A10,Baris_Transaksi!$E$5:$E$5000) -> 0 | F10: =IF(D10-E10>0,D10-E10,0) -> 0 | G10: =IF(E10-D10>0,E10-D10,0) -> 0 | H10: =IF(OR(C10="Aset",C10="Perbelanjaan"),D10-E10,E10-D10) -> 0
A11: =Akaun!A11 -> 1070 | B11: =Akaun!C11 -> Inventori Ayam & Produk Sembelihan | C11: =Akaun!D11 -> Aset | D11: =SUMIF(Baris_Transaksi!$C$5:$C$5000,A11,Baris_Transaksi!$D$5:$D$5000) -> 0 | E11: =SUMIF(Baris_Transaksi!$C$5:$C$5000,A11,Baris_Transaksi!$E$5:$E$5000) -> 0 | F11: =IF(D11-E11>0,D11-E11,0) -> 0 | G11: =IF(E11-D11>0,E11-D11,0) -> 0 | H11: =IF(OR(C11="Aset",C11="Perbelanjaan"),D11-E11,E11-D11) -> 0
A12: =Akaun!A12 -> 2010 | B12: =Akaun!C12 -> Pelbagai Pemiutang | C12: =Akaun!D12 -> Liabiliti | D12: =SUMIF(Baris_Transaksi!$C$5:$C$5000,A12,Baris_Transaksi!$D$5:$D$5000) -> 0 | E12: =SUMIF(Baris_Transaksi!$C$5:$C$5000,A12,Baris_Transaksi!$E$5:$E$5000) -> 0 | F12: =IF(D12-E12>0,D12-E12,0) -> 0 | G12: =IF(E12-D12>0,E12-D12,0) -> 0 | H12: =IF(OR(C12="Aset",C12="Perbelanjaan"),D12-E12,E12-D12) -> 0
A13: =Akaun!A13 -> 2020 | B13: =Akaun!C13 -> Dividen Diisytiharkan | C13: =Akaun!D13 -> Liabiliti | D13: =SUMIF(Baris_Transaksi!$C$5:$C$5000,A13,Baris_Transaksi!$D$5:$D$5000) -> 0 | E13: =SUMIF(Baris_Transaksi!$C$5:$C$5000,A13,Baris_Transaksi!$E$5:$E$5000) -> 0 | F13: =IF(D13-E13>0,D13-E13,0) -> 0 | G13: =IF(E13-D13>0,E13-D13,0) -> 0 | H13: =IF(OR(C13="Aset",C13="Perbelanjaan"),D13-E13,E13-D13) -> 0
A14: =Akaun!A14 -> 3010 | B14: =Akaun!C14 -> Modal Syer Ahli | C14: =Akaun!D14 -> Ekuiti | D14: =SUMIF(Baris_Transaksi!$C$5:$C$5000,A14,Baris_Transaksi!$D$5:$D$5000) -> 0 | E14: =SUMIF(Baris_Transaksi!$C$5:$C$5000,A14,Baris_Transaksi!$E$5:$E$5000) -> 0 | F14: =IF(D14-E14>0,D14-E14,0) -> 0 | G14: =IF(E14-D14>0,E14-D14,0) -> 0 | H14: =IF(OR(C14="Aset",C14="Perbelanjaan"),D14-E14,E14-D14) -> 0
A15: =Akaun!A15 -> 3020 | B15: =Akaun!C15 -> Rizab Statutori | C15: =Akaun!D15 -> Ekuiti | D15: =SUMIF(Baris_Transaksi!$C$5:$C$5000,A15,Baris_Transaksi!$D$5:$D$5000) -> 0 | E15: =SUMIF(Baris_Transaksi!$C$5:$C$5000,A15,Baris_Transaksi!$E$5:$E$5000) -> 0 | F15: =IF(D15-E15>0,D15-E15,0) -> 0 | G15: =IF(E15-D15>0,E15-D15,0) -> 0 | H15: =IF(OR(C15="Aset",C15="Perbelanjaan"),D15-E15,E15-D15) -> 0
A16: =Akaun!A16 -> 3030 | B16: =Akaun!C16 -> Lebihan Terkumpul | C16: =Akaun!D16 -> Ekuiti | D16: =SUMIF(Baris_Transaksi!$C$5:$C$5000,A16,Baris_Transaksi!$D$5:$D$5000) -> 0 | E16: =SUMIF(Baris_Transaksi!$C$5:$C$5000,A16,Baris_Transaksi!$E$5:$E$5000) -> 0 | F16: =IF(D16-E16>0,D16-E16,0) -> 0 | G16: =IF(E16-D16>0,E16-D16,0) -> 0 | H16: =IF(OR(C16="Aset",C16="Perbelanjaan"),D16-E16,E16-D16) -> 0
... A150: =Akaun!A150 -> 0 | B150: =Akaun!C150 -> 0 | C150: =Akaun!D150 -> 0 | D150: =SUMIF(Baris_Transaksi!$C$5:$C$5000,A150,Baris_Transaksi!$D$5:$D$5000) -> 0 | E150: =SUMIF(Baris_Transaksi!$C$5:$C$5000,A150,Baris_Transaksi!$E$5:$E$5000) -> 0 | F150: =IF(D150-E150>0,D150-E150,0) -> 0 | G150: =IF(E150-D150>0,E150-D150,0) -> 0 | H150: =IF(OR(C150="Aset",C150="Perbelanjaan"),D150-E150,E150-D150) -> 0
A151: JUMLAH | F151: =SUM(F5:F150) -> 0 | G151: =SUM(G5:G150) -> 0
A153: Semakan: | B153: =IF(ROUND(F151-G151,2)=0,"SEIMBANG","TIDAK SEIMBANG - beza RM"&TEXT(F151-G151,"#,##0.00")) -> SEIMBANG
A154: Kapasiti lejar (baris digunakan): | B154: =COUNTA(Baris_Transaksi!$B$5:$B$5000)&" / 4996" -> 0 / 4996 | C154: =IF(COUNTA(Baris_Transaksi!$B$5:$B$5000)>4996*0.9,"HAMPIR PENUH - lebarkan julat formula","OK") -> OK

Sheet UR
A1: AKAUN UNTUNG RUGI (INCOME STATEMENT)
A2: Bagi tempoh [isi tarikh mula] hingga [isi tarikh akhir]. Cukai, Zakat, Honorarium dan KWA kini di APK, bukan di sini.
A4: HASIL
A5: Fi Masuk | B5: =SUMIF(Imbangan_Duga!$A$5:$A$150,4010,Imbangan_Duga!$H$5:$H$150) -> 0
A6: Faedah Bank | B6: =SUMIF(Imbangan_Duga!$A$5:$A$150,4020,Imbangan_Duga!$H$5:$H$150) -> 0
A7: Hibah Bank | B7: =SUMIF(Imbangan_Duga!$A$5:$A$150,4030,Imbangan_Duga!$H$5:$H$150) -> 0
A8: Jualan Runcit | B8: =SUMIF(Imbangan_Duga!$A$5:$A$150,4040,Imbangan_Duga!$H$5:$H$150) -> 0
A9: Pendapatan Perkhidmatan | B9: =SUMIF(Imbangan_Duga!$A$5:$A$150,4050,Imbangan_Duga!$H$5:$H$150) -> 0
A10: Pendapatan Latihan & Kursus | B10: =SUMIF(Imbangan_Duga!$A$5:$A$150,4060,Imbangan_Duga!$H$5:$H$150) -> 0
A11: Jualan Makanan & Minuman | B11: =SUMIF(Imbangan_Duga!$A$5:$A$150,4070,Imbangan_Duga!$H$5:$H$150) -> 0
A12: Jualan Ayam & Produk Sembelihan | B12: =SUMIF(Imbangan_Duga!$A$5:$A$150,4080,Imbangan_Duga!$H$5:$H$150) -> 0
A13: JUMLAH HASIL | B13: =SUMIF(Imbangan_Duga!$C$5:$C$150,"Hasil",Imbangan_Duga!$H$5:$H$150) -> 0
A15: PERBELANJAAN OPERASI
A16: Perbelanjaan Pejabat | B16: =SUMIF(Imbangan_Duga!$A$5:$A$150,5010,Imbangan_Duga!$H$5:$H$150) -> 0
A17: Perbelanjaan Lembaga | B17: =SUMIF(Imbangan_Duga!$A$5:$A$150,5020,Imbangan_Duga!$H$5:$H$150) -> 0
A18: Gaji dan Elaun | B18: =SUMIF(Imbangan_Duga!$A$5:$A$150,5030,Imbangan_Duga!$H$5:$H$150) -> 0
A19: Alatulis dan Percetakan | B19: =SUMIF(Imbangan_Duga!$A$5:$A$150,5040,Imbangan_Duga!$H$5:$H$150) -> 0
A20: Fi Juruaudit | B20: =SUMIF(Imbangan_Duga!$A$5:$A$150,5050,Imbangan_Duga!$H$5:$H$150) -> 0
A21: Fi Perakaunan | B21: =SUMIF(Imbangan_Duga!$A$5:$A$150,5060,Imbangan_Duga!$H$5:$H$150) -> 0
A22: Caj Bank | B22: =SUMIF(Imbangan_Duga!$A$5:$A$150,5070,Imbangan_Duga!$H$5:$H$150) -> 0
A23: Mesyuarat Agung Tahunan | B23: =SUMIF(Imbangan_Duga!$A$5:$A$150,5080,Imbangan_Duga!$H$5:$H$150) -> 0
A24: Mesyuarat Agung Khas | B24: =SUMIF(Imbangan_Duga!$A$5:$A$150,5090,Imbangan_Duga!$H$5:$H$150) -> 0
A25: Internet dan Telefon | B25: =SUMIF(Imbangan_Duga!$A$5:$A$150,5150,Imbangan_Duga!$H$5:$H$150) -> 0
A26: Susut Nilai Aset | B26: =SUMIF(Imbangan_Duga!$A$5:$A$150,5160,Imbangan_Duga!$H$5:$H$150) -> 0
A27: Belian Runcit | B27: =SUMIF(Imbangan_Duga!$A$5:$A$150,5180,Imbangan_Duga!$H$5:$H$150) -> 0
A28: Kos Latihan & Kursus | B28: =SUMIF(Imbangan_Duga!$A$5:$A$150,5190,Imbangan_Duga!$H$5:$H$150) -> 0
A29: Kos Bahan Mentah F&B | B29: =SUMIF(Imbangan_Duga!$A$5:$A$150,5200,Imbangan_Duga!$H$5:$H$150) -> 0
A30: Belian Ayam Hidup | B30: =SUMIF(Imbangan_Duga!$A$5:$A$150,5210,Imbangan_Duga!$H$5:$H$150) -> 0
A31: Kos Sembelihan & Pemprosesan | B31: =SUMIF(Imbangan_Duga!$A$5:$A$150,5220,Imbangan_Duga!$H$5:$H$150) -> 0
A32: Fi Pensijilan Halal | B32: =SUMIF(Imbangan_Duga!$A$5:$A$150,5230,Imbangan_Duga!$H$5:$H$150) -> 0
A33: Pelbagai Perbelanjaan | B33: =SUMIF(Imbangan_Duga!$A$5:$A$150,5170,Imbangan_Duga!$H$5:$H$150) -> 0
A34: JUMLAH PERBELANJAAN OPERASI | B34: =SUMIF(Imbangan_Duga!$C$5:$C$150,"Perbelanjaan",Imbangan_Duga!$H$5:$H$150) -> 0
A36: LEBIHAN BERSIH (SURPLUS) - SEBELUM PEMBAHAGIAN | B36: =B13-B34 -> 0

Sheet APK
A1: AKAUN PEMBAHAGIAN KEUNTUNGAN (APK)
A2: Bagi tempoh [isi tarikh mula] hingga [isi tarikh akhir]. Lajur kuning = keputusan Lembaga, isi semasa mesyuarat.
A4: Lebihan Bersih Tahun Semasa (daripada UR) | B4: =UR!B36 -> 0
A6: TOLAK: PEMBAHAGIAN BERKANUN
A7: Kumpulan Wang Rizab Statutori (Tetapan!C15) | B7: =B4*Tetapan!C15/100 -> 0
A8: Kumpulan Wang Amanah Pendidikan Koperasi (Tetapan!C16) | B8: =B4*Tetapan!C16/100 -> 0
A9: Kumpulan Wang Amanah Pembangunan Koperasi (Tetapan!C17) | B9: =B4*Tetapan!C17/100 -> 0
A10: JUMLAH PEMBAHAGIAN BERKANUN | B10: =SUM(B7:B9) -> 0
A12: LEBIHAN SELEPAS PEMBAHAGIAN BERKANUN | B12: =B4-B10 -> 0
A14: TOLAK: PERUNTUKAN
A15: Peruntukan Cukai Pendapatan (isi anggaran Lembaga) | B15: 0
A16: Peruntukan Zakat (isi anggaran Lembaga) | B16: 0
A17: JUMLAH PERUNTUKAN | B17: =SUM(B15:B16) -> 0
A19: TOLAK: LAIN-LAIN PEMBAHAGIAN (cadangan Lembaga)
A20: Dividen Atas Modal Syer (isi cadangan) | B20: 0
A21: Dividen Atas Modal Yuran (isi cadangan) | B21: 0
A22: Honorarium Lembaga (isi cadangan) | B22: 0
A23: JUMLAH LAIN-LAIN PEMBAHAGIAN | B23: =SUM(B20:B22) -> 0
A25: BAKI KEUNTUNGAN BELUM DIBAHAGI-BAHAGIKAN | B25: =B12-B17-B23 -> 0
A27: Tambah: Lebihan Terkumpul Pada Awal Tahun | B27: =SUMIF(Imbangan_Duga!$A$5:$A$150,3030,Imbangan_Duga!$H$5:$H$150) -> 0
A28: LEBIHAN TERKUMPUL PADA AKHIR TAHUN (unjuran) | B28: =B25+B27 -> 0
A30: Nota
A31: Baris B28 ialah UNJURAN untuk keputusan Lembaga, bukan baki sebenar KKK - KKK kekal tunjuk baki sebenar lejar. Selepas Lembaga luluskan angka di atas, pos SATU transaksi seimbang: Debit Lebihan Terkumpul (3030) sebanyak jumlah yang diluluskan, Kredit setiap akaun liabiliti berkaitan (Rizab Statutori 3020, KWA Pendidikan Belum Dibayar 2100, KWA Pembangunan Belum Dibayar 2110, Cukai Belum Dibayar 2070, Zakat Belum Dibayar 2080, Dividen Diisytiharkan 2020, Honorarium Belum Dibayar 2090). Selepas itu KKK automatik betul.

Sheet KKK
A1: KUNCI KIRA-KIRA (BALANCE SHEET)
A2: Setakat [isi tarikh penyata]
A4: ASET
A5: Wang Di Tangan | B5: =SUMIF(Imbangan_Duga!$A$5:$A$150,1010,Imbangan_Duga!$H$5:$H$150) -> 0
A6: Bank | B6: =SUMIF(Imbangan_Duga!$A$5:$A$150,1020,Imbangan_Duga!$H$5:$H$150) -> 0
A7: Deposit Tetap | B7: =SUMIF(Imbangan_Duga!$A$5:$A$150,1030,Imbangan_Duga!$H$5:$H$150) -> 0
A8: Aset Tetap | B8: =SUMIF(Imbangan_Duga!$A$5:$A$150,1040,Imbangan_Duga!$H$5:$H$150) -> 0
A9: Akaun Deposit Koperasi | B9: =SUMIF(Imbangan_Duga!$A$5:$A$150,1050,Imbangan_Duga!$H$5:$H$150) -> 0
A10: Inventori Runcit | B10: =SUMIF(Imbangan_Duga!$A$5:$A$150,1060,Imbangan_Duga!$H$5:$H$150) -> 0
A11: Inventori Ayam & Produk Sembelihan | B11: =SUMIF(Imbangan_Duga!$A$5:$A$150,1070,Imbangan_Duga!$H$5:$H$150) -> 0
A12: JUMLAH ASET | B12: =SUMIF(Imbangan_Duga!$C$5:$C$150,"Aset",Imbangan_Duga!$H$5:$H$150) -> 0
A14: LIABILITI
A15: Pelbagai Pemiutang | B15: =SUMIF(Imbangan_Duga!$A$5:$A$150,2010,Imbangan_Duga!$H$5:$H$150) -> 0
A16: Dividen Diisytiharkan | B16: =SUMIF(Imbangan_Duga!$A$5:$A$150,2020,Imbangan_Duga!$H$5:$H$150) -> 0
A17: JUMLAH LIABILITI | B17: =SUMIF(Imbangan_Duga!$C$5:$C$150,"Liabiliti",Imbangan_Duga!$H$5:$H$150) -> 0
A19: EKUITI AHLI
A20: Modal Syer Ahli | B20: =SUMIF(Imbangan_Duga!$A$5:$A$150,3010,Imbangan_Duga!$H$5:$H$150) -> 0
A21: Rizab Statutori | B21: =SUMIF(Imbangan_Duga!$A$5:$A$150,3020,Imbangan_Duga!$H$5:$H$150) -> 0
A22: Lebihan Terkumpul (Tahun Lepas) | B22: =SUMIF(Imbangan_Duga!$A$5:$A$150,3030,Imbangan_Duga!$H$5:$H$150) -> 0
A23: Lebihan Tahun Semasa | B23: =UR!B36 -> 0
A24: JUMLAH EKUITI AHLI | B24: =SUM(B20:B23) -> 0
A26: JUMLAH LIABILITI + EKUITI | B26: =B17+B24 -> 0
A28: Semakan: | B28: =IF(ROUND(B12-B26,2)=0,"SEIMBANG","TIDAK SEIMBANG - beza RM"&TEXT(B12-B26,"#,##0.00")) -> SEIMBANG

Sheet AT
A1: PENYATA ALIRAN TUNAI (CASH FLOW STATEMENT)
A2: Bagi tempoh [isi tarikh mula] hingga [isi tarikh akhir] — kaedah tidak langsung (indirect method)
A4: AKTIVITI OPERASI
A5: Lebihan bersih (daripada UR) | B5: =UR!B36 -> 0
A6: Pelarasan lain (pilihan - biar 0) | B6: 0
A7: Modal kerja & pelarasan bukan tunai (AUTO) | B7: =SUMIFS(Baris_Transaksi!$E$5:$E$5000,Baris_Transaksi!$G$5:$G$5000,"Operasi",Baris_Transaksi!$H$5:$H$5000,"Aset",Baris_Transaksi!$B$5:$B$5000,"<>"&Tetapan!$C$18)-SUMIFS(Baris_Transaksi!$D$5:$D$5000,Baris_Transaksi!$G$5:$G$5000,"Operasi",Baris_Transaksi!$H$5:$H$5000,"Aset",Baris_Transaksi!$B$5:$B$5000,"<>"&Tetapan!$C$18)+SUMIFS(Baris_Transaksi!$E$5:$E$5000,Baris_Transaksi!$G$5:$G$5000,"Operasi",Baris_Transaksi!$H$5:$H$5000,"Liabiliti",Baris_Transaksi!$B$5:$B$5000,"<>"&Tetapan!$C$18)-SUMIFS(Baris_Transaksi!$D$5:$D$5000,Baris_Transaksi!$G$5:$G$5000,"Operasi",Baris_Transaksi!$H$5:$H$5000,"Liabiliti",Baris_Transaksi!$B$5:$B$5000,"<>"&Tetapan!$C$18) -> 0
A8: TUNAI BERSIH DARIPADA OPERASI | B8: =SUM(B5:B7) -> 0
A10: AKTIVITI PELABURAN
A11: Pergerakan bersih akaun pelaburan/aset tetap (cth. Deposit Tetap, Tanah, Bangunan) | B11: =SUMIFS(Baris_Transaksi!$E$5:$E$5000,Baris_Transaksi!$G$5:$G$5000,"Pelaburan",Baris_Transaksi!$B$5:$B$5000,"<>"&Tetapan!$C$18)-SUMIFS(Baris_Transaksi!$D$5:$D$5000,Baris_Transaksi!$G$5:$G$5000,"Pelaburan",Baris_Transaksi!$B$5:$B$5000,"<>"&Tetapan!$C$18) -> 0
A12: TUNAI BERSIH DARIPADA PELABURAN | B12: =B11 -> 0
A14: AKTIVITI PEMBIAYAAN
A15: Pergerakan bersih modal syer, simpanan ahli, pinjaman & dividen dibayar | B15: =SUMIFS(Baris_Transaksi!$E$5:$E$5000,Baris_Transaksi!$G$5:$G$5000,"Pembiayaan",Baris_Transaksi!$B$5:$B$5000,"<>"&Tetapan!$C$18)-SUMIFS(Baris_Transaksi!$D$5:$D$5000,Baris_Transaksi!$G$5:$G$5000,"Pembiayaan",Baris_Transaksi!$B$5:$B$5000,"<>"&Tetapan!$C$18) -> 0
A16: TUNAI BERSIH DARIPADA PEMBIAYAAN | B16: =B15 -> 0
A17: AKTIVITI BERKANUN (Bayaran Berkanun & Agihan)
A18: Bayaran kepada KWRS/KWA Pendidikan/Pembangunan/Cukai/Zakat/Honorarium/Dividen (hanya bahagian dibayar) | B18: =-SUMIFS(Baris_Transaksi!$D$5:$D$5000,Baris_Transaksi!$G$5:$G$5000,"Berkanun",Baris_Transaksi!$B$5:$B$5000,"<>"&Tetapan!$C$18) -> 0
A19: TUNAI BERSIH DARIPADA AKTIVITI BERKANUN | B19: =B18 -> 0
A21: PERUBAHAN BERSIH TUNAI (B8+B12+B16+B19) | B21: =B8+B12+B16+B19 -> 0
A23: Tunai & bank pada awal tempoh (semua akaun wang) | B23: =SUMIFS(Baris_Transaksi!$D$5:$D$5000,Baris_Transaksi!$G$5:$G$5000,"Tidak Berkaitan",Baris_Transaksi!$H$5:$H$5000,"Aset",Baris_Transaksi!$B$5:$B$5000,Tetapan!$C$18)-SUMIFS(Baris_Transaksi!$E$5:$E$5000,Baris_Transaksi!$G$5:$G$5000,"Tidak Berkaitan",Baris_Transaksi!$H$5:$H$5000,"Aset",Baris_Transaksi!$B$5:$B$5000,Tetapan!$C$18) -> 0
A24: TUNAI & BANK PADA AKHIR TEMPOH (dikira) | B24: =B23+B21 -> 0
A25: Tunai & bank pada akhir tempoh (semakan bebas, dari Imbangan_Duga) | B25: =SUMPRODUCT((Akaun!$D$5:$D$150="Aset")*(Akaun!$F$5:$F$150="Tidak Berkaitan")*Imbangan_Duga!$H$5:$H$150) -> 0
A27: Semakan: | B27: =IF(ROUND(B24-B25,2)=0,"SEIMBANG","TIDAK SEIMBANG - beza RM"&TEXT(B24-B25,"#,##0.00")) -> SEIMBANG

Sheet Wang_Runcit
A1: WANG RUNCIT (PETTY CASH) — SEMAKAN
A2: Setiap perbelanjaan runcit dicatat terus: Debit akaun perbelanjaan, Kredit Wang Runcit (1080). Isi semula (float top-up): Debit Wang Runcit, Kredit Bank.
A4: Float ditetapkan / diisytiharkan (RM) - rujukan sahaja
A5: Baki mengikut buku (Wang Runcit, kod 1080) | B5: =SUMIF(Imbangan_Duga!$A$5:$A$150,1080,Imbangan_Duga!$H$5:$H$150) -> 0
A6: Tarikh pengiraan fizikal terakhir
A7: Baki dikira semasa pengiraan fizikal (kira duit sebenar dalam tin/peti)
A9: PERBEZAAN (Baki Buku - Baki Fizikal) | B9: =IF(B7="","",B5-B7)
A10: Status | B10: =IF(B7="","BELUM DIKIRA",IF(ROUND(B9,2)=0,"SEPADAN","PERLU SIASAT - lihat lajur Nota di Baris_Transaksi untuk perbelanjaan terbaru")) -> BELUM DIKIRA
A12: Nota
A13: Baki Buku di atas ialah baki SEBENAR akaun 1080 dalam lejar - bukan dikira daripada float. Sebelum guna helaian ini, catat SATU transaksi "wujudkan float": Debit Wang Runcit RM{float}, Kredit Bank/Wang Di Tangan RM{float}, dalam Baris_Transaksi. Selepas itu, setiap perbelanjaan runcit ialah Debit akaun perbelanjaan, Kredit Wang Runcit - baki di atas turun sendiri ikut perbelanjaan sebenar, tiada pengiraan tambahan diperlukan.

Sheet Cetak
A1: =Tetapan!C5 -> [Isi nama koperasi sebenar di sini]
A2: PENYATA KEWANGAN
A3: Disediakan untuk Mesyuarat Lembaga
A5: RINGKASAN KEDUDUKAN KEWANGAN (AI)
A6: (Jalankan menu APZacct > Jana Ringkasan AI untuk isi bahagian ini. Kosong sehingga itu — tidak akan menghalang cetakan penyata di bawah.)
A13: =KKK!A1 -> KUNCI KIRA-KIRA (BALANCE SHEET)
A14: =KKK!A2 -> Setakat [isi tarikh penyata]
A15: =KKK!A4 -> ASET
A16: =KKK!A5 -> Wang Di Tangan | B16: =KKK!B5 -> 0
A17: =KKK!A6 -> Bank | B17: =KKK!B6 -> 0
A18: =KKK!A7 -> Deposit Tetap | B18: =KKK!B7 -> 0
A19: =KKK!A8 -> Aset Tetap | B19: =KKK!B8 -> 0
A20: =KKK!A9 -> Akaun Deposit Koperasi | B20: =KKK!B9 -> 0
A21: =KKK!A10 -> Inventori Runcit | B21: =KKK!B10 -> 0
A22: =KKK!A11 -> Inventori Ayam & Produk Sembelihan | B22: =KKK!B11 -> 0
A23: =KKK!A12 -> JUMLAH ASET | B23: =KKK!B12 -> 0
A24: =KKK!A14 -> LIABILITI
A25: =KKK!A15 -> Pelbagai Pemiutang | B25: =KKK!B15 -> 0
A26: =KKK!A16 -> Dividen Diisytiharkan | B26: =KKK!B16 -> 0
A27: =KKK!A17 -> JUMLAH LIABILITI | B27: =KKK!B17 -> 0
A28: =KKK!A19 -> EKUITI AHLI
A29: =KKK!A20 -> Modal Syer Ahli | B29: =KKK!B20 -> 0
A30: =KKK!A21 -> Rizab Statutori | B30: =KKK!B21 -> 0
A31: =KKK!A22 -> Lebihan Terkumpul (Tahun Lepas) | B31: =KKK!B22 -> 0
A32: =KKK!A23 -> Lebihan Tahun Semasa | B32: =KKK!B23 -> 0
A33: =KKK!A24 -> JUMLAH EKUITI AHLI | B33: =KKK!B24 -> 0
A34: =KKK!A26 -> JUMLAH LIABILITI + EKUITI | B34: =KKK!B26 -> 0
A35: =KKK!A28 -> Semakan: | B35: =KKK!B28 -> SEIMBANG
A39: =UR!A1 -> AKAUN UNTUNG RUGI (INCOME STATEMENT)
A40: =UR!A2 -> Bagi tempoh [isi tarikh mula] hingga [isi tarikh akhir]. Cukai, Zakat, Honorarium dan KWA kini di APK, bukan di sini.
A41: =UR!A4 -> HASIL
A42: =UR!A5 -> Fi Masuk | B42: =UR!B5 -> 0
A43: =UR!A6 -> Faedah Bank | B43: =UR!B6 -> 0
A44: =UR!A7 -> Hibah Bank | B44: =UR!B7 -> 0
A45: =UR!A8 -> Jualan Runcit | B45: =UR!B8 -> 0
A46: =UR!A9 -> Pendapatan Perkhidmatan | B46: =UR!B9 -> 0
A47: =UR!A10 -> Pendapatan Latihan & Kursus | B47: =UR!B10 -> 0
A48: =UR!A11 -> Jualan Makanan & Minuman | B48: =UR!B11 -> 0
A49: =UR!A12 -> Jualan Ayam & Produk Sembelihan | B49: =UR!B12 -> 0
A50: =UR!A13 -> JUMLAH HASIL | B50: =UR!B13 -> 0
...

Sheet Nota
A1: NOTA-NOTA KEPADA AKAUN (NOTES TO THE ACCOUNTS) — TEMPLAT GP23 (v1.3)
A2: Templat ini untuk MANA-MANA jenis koperasi, tanpa kira aktiviti. Formula TIDAK dikodkeras kepada kod akaun tertentu — setiap Nota bertanya "Berkaitan?" dan "Kod Akaun", diisi dengan kod SEBENAR koperasi anda sendiri (daripada helaian Akaun anda sendiri). Jika Tidak Berkaitan, biar kod kosong — baki tunjuk 0, itu betul.
A3: Nilai akan terpapar selepas transaksi dipos. Sebarang angka contoh dalam panduan atau ujian ialah DATA UJIAN sahaja — bukan kedudukan kewangan sebenar mana-mana koperasi.
A5: NOTA 1 — MAKLUMAT UMUM (GP23 perenggan 16, Nota 1)
A6: Aktiviti utama | B6: [ISI] ◄ ISI
A7: Alamat berdaftar | B7: [ISI] ◄ ISI
A8: No. Pendaftaran SKM | B8: =IF(Tetapan!C6="","[ISI di Tetapan!C6]",Tetapan!C6) -> [ISI di Tetapan!C6]
A10: NOTA 2 — ASAS PENYEDIAAN PENYATA KEWANGAN (GP23 perenggan 16, Nota 2)
A11: Penyata kewangan ini disediakan mengikut piawaian perakaunan yang diluluskan di Malaysia (MPERS), sebagaimana diubahsuaikan oleh GP23: Garis Panduan Pelaporan Penyata Kewangan Koperasi, selaras dengan Akta Koperasi 1993 dan Peraturan-Peraturan Koperasi 2010. [ISI jika koperasi anda menggunakan piawaian lain]
A13: NOTA 3 — TARIKH PENGESAHAN PENYATA KEWANGAN (GP23 perenggan 16, Nota 3)
A14: Disahkan oleh Lembaga pada | B14: [ISI] ◄ ISI
A16: NOTA 4 — RINGKASAN POLISI PERAKAUNAN PENTING (GP23 perenggan 16, Nota 5)
A17: (a) Susut nilai — kaedah/kadar setiap aset (daripada Daftar_Aset_Tetap; kosong jika belum ada aset didaftar):
A18: Nama Aset | B18: Kategori | C18: Kaedah | D18: Kadar
A19: =IF(Daftar_Aset_Tetap!A5="","",Daftar_Aset_Tetap!A5) | B19: =IF(Daftar_Aset_Tetap!A5="","",Daftar_Aset_Tetap!B5) | C19: =IF(Daftar_Aset_Tetap!A5="","",Daftar_Aset_Tetap!G5) | D19: =IF(Daftar_Aset_Tetap!A5="","",Daftar_Aset_Tetap!H5)
A20: =IF(Daftar_Aset_Tetap!A6="","",Daftar_Aset_Tetap!A6) | B20: =IF(Daftar_Aset_Tetap!A6="","",Daftar_Aset_Tetap!B6) | C20: =IF(Daftar_Aset_Tetap!A6="","",Daftar_Aset_Tetap!G6) | D20: =IF(Daftar_Aset_Tetap!A6="","",Daftar_Aset_Tetap!H6)
A21: =IF(Daftar_Aset_Tetap!A7="","",Daftar_Aset_Tetap!A7) | B21: =IF(Daftar_Aset_Tetap!A7="","",Daftar_Aset_Tetap!B7) | C21: =IF(Daftar_Aset_Tetap!A7="","",Daftar_Aset_Tetap!G7) | D21: =IF(Daftar_Aset_Tetap!A7="","",Daftar_Aset_Tetap!H7)
A22: =IF(Daftar_Aset_Tetap!A8="","",Daftar_Aset_Tetap!A8) | B22: =IF(Daftar_Aset_Tetap!A8="","",Daftar_Aset_Tetap!B8) | C22: =IF(Daftar_Aset_Tetap!A8="","",Daftar_Aset_Tetap!G8) | D22: =IF(Daftar_Aset_Tetap!A8="","",Daftar_Aset_Tetap!H8)
A23: =IF(Daftar_Aset_Tetap!A9="","",Daftar_Aset_Tetap!A9) | B23: =IF(Daftar_Aset_Tetap!A9="","",Daftar_Aset_Tetap!B9) | C23: =IF(Daftar_Aset_Tetap!A9="","",Daftar_Aset_Tetap!G9) | D23: =IF(Daftar_Aset_Tetap!A9="","",Daftar_Aset_Tetap!H9)
A24: =IF(Daftar_Aset_Tetap!A10="","",Daftar_Aset_Tetap!A10) | B24: =IF(Daftar_Aset_Tetap!A10="","",Daftar_Aset_Tetap!B10) | C24: =IF(Daftar_Aset_Tetap!A10="","",Daftar_Aset_Tetap!G10) | D24: =IF(Daftar_Aset_Tetap!A10="","",Daftar_Aset_Tetap!H10)
A25: =IF(Daftar_Aset_Tetap!A11="","",Daftar_Aset_Tetap!A11) | B25: =IF(Daftar_Aset_Tetap!A11="","",Daftar_Aset_Tetap!B11) | C25: =IF(Daftar_Aset_Tetap!A11="","",Daftar_Aset_Tetap!G11) | D25: =IF(Daftar_Aset_Tetap!A11="","",Daftar_Aset_Tetap!H11)
A26: =IF(Daftar_Aset_Tetap!A12="","",Daftar_Aset_Tetap!A12) | B26: =IF(Daftar_Aset_Tetap!A12="","",Daftar_Aset_Tetap!B12) | C26: =IF(Daftar_Aset_Tetap!A12="","",Daftar_Aset_Tetap!G12) | D26: =IF(Daftar_Aset_Tetap!A12="","",Daftar_Aset_Tetap!H12)
A27: =IF(Daftar_Aset_Tetap!A13="","",Daftar_Aset_Tetap!A13) | B27: =IF(Daftar_Aset_Tetap!A13="","",Daftar_Aset_Tetap!B13) | C27: =IF(Daftar_Aset_Tetap!A13="","",Daftar_Aset_Tetap!G13) | D27: =IF(Daftar_Aset_Tetap!A13="","",Daftar_Aset_Tetap!H13)
A28: =IF(Daftar_Aset_Tetap!A14="","",Daftar_Aset_Tetap!A14) | B28: =IF(Daftar_Aset_Tetap!A14="","",Daftar_Aset_Tetap!B14) | C28: =IF(Daftar_Aset_Tetap!A14="","",Daftar_Aset_Tetap!G14) | D28: =IF(Daftar_Aset_Tetap!A14="","",Daftar_Aset_Tetap!H14)
A29: (b) Inventori | B29: Pada kos, atau kos/nilai boleh direalisasi bersih (mana lebih rendah). [ISI jika berbeza] ◄ ISI
A30: (c) Hutang ragu/lapuk | B30: [ISI polisi — cth. GP23 wajibkan ini bagi pinjaman >6 bulan tak berbayar] ◄ ISI
A31: (d) Pengiktirafan hasil | B31: [ISI — bagaimana setiap aktiviti mengiktiraf pendapatan] ◄ ISI
A32: (e) Usaha berterusan | B32: Disediakan berasaskan usaha berterusan. [ISI "TIDAK" + sebab jika tidak lagi benar] ◄ ISI
A34: NOTA 5 — POLISI RISIKO PENGURUSAN KEWANGAN (GP23 Lampiran 5 perenggan 6)
A35: (a) Risiko Kecairan: [ISI] ◄ ISI
A36: (b) Risiko Kredit: [ISI] ◄ ISI
A38: NOTA 6 — HARTA TANAH, LOJI DAN PERALATAN (PPE) (GP23 perenggan 15(a))
A39: Berkaitan untuk koperasi ini? | B39: [ISI — Ya/Tidak] ◄ ISI
A40: Kod Akaun — Kos PPE | B40: [ISI kod akaun] ◄ ISI
A41: Kod Akaun — Susut Nilai Terkumpul | B41: [ISI kod akaun] ◄ ISI
A42: Baki awal tahun (Sejarah_Baki jika ada) | B42: =IF($B$40="","",IFERROR(SUMIF(Sejarah_Baki!$B:$B,$B$40,Sejarah_Baki!$D:$D)-SUMIF(Sejarah_Baki!$B:$B,$B$40,Sejarah_Baki!$E:$E),"[ISI—thn pertama]")) -> 0
A43: Tambahan tahun semasa | B43: =IF($B$40="",0,SUMIFS(Baris_Transaksi!$D:$D,Baris_Transaksi!$C:$C,$B$40,Baris_Transaksi!$B:$B,"<>"&Tetapan!$C$18)) -> 0
A44: Pengurangan tahun semasa | B44: =IF($B$40="",0,SUMIFS(Baris_Transaksi!$E:$E,Baris_Transaksi!$C:$C,$B$40,Baris_Transaksi!$B:$B,"<>"&Tetapan!$C$18)) -> 0
A45: Baki akhir tahun (semakan bebas) | B45: =IF($B$40="",0,SUMIF(Imbangan_Duga!$A:$A,$B$40,Imbangan_Duga!$H:$H)) -> 0
A46: Susut Nilai Terkumpul (semakan bebas) | B46: =IF($B$41="",0,SUMIF(Imbangan_Duga!$A:$A,$B$41,Imbangan_Duga!$H:$H)) -> 0
...

Sheet Sejarah_Baki
A1: Tahun (baki ditutup) | B1: Kod Akaun | C1: Nama Akaun | D1: Debit | E1: Kredit
